2023-11-11 15:21:46,712 - pyswarms.single.global_best - INFO - Optimize for 10 iters with {'c1': 0.5, 'c2': 0.3, 'w': 0.9}
2023-11-11 15:26:25,460 - pyswarms.single.global_best - INFO - Optimize for 10 iters with {'c1': 0.5, 'c2': 0.3, 'w': 0.9}
2023-11-11 15:28:41,036 - pyswarms.single.global_best - INFO - Optimize for 10 iters with {'c1': 0.5, 'c2': 0.3, 'w': 0.9}
2023-11-11 15:29:46,398 - pyswarms.single.global_best - INFO - Optimize for 10 iters with {'c1': 0.5, 'c2': 0.3, 'w': 0.9}
2023-11-11 15:29:54,797 - pyswarms.single.global_best - INFO - Optimize for 10 iters with {'c1': 0.5, 'c2': 0.3, 'w': 0.9}
2023-11-11 15:32:20,141 - concurrent.futures - ERROR - exception calling callback for <Future at 0x18e29029160 state=finished raised TerminatedWorkerError>
Traceback (most recent call last):
  File "c:\Users\Asus\anaconda3\lib\site-packages\joblib\externals\loky\_base.py", line 625, in _invoke_callbacks
  File "c:\Users\Asus\anaconda3\lib\site-packages\joblib\parallel.py", line 359, in __call__
    **backend_params
  File "c:\Users\Asus\anaconda3\lib\site-packages\joblib\parallel.py", line 794, in dispatch_next
    # registers the task outcome (TASK_ERROR or TASK_DONE), and schedules
  File "c:\Users\Asus\anaconda3\lib\site-packages\joblib\parallel.py", line 861, in dispatch_one_batch
    with self.parallel._lock:
  File "c:\Users\Asus\anaconda3\lib\site-packages\joblib\parallel.py", line 779, in _dispatch
  File "c:\Users\Asus\anaconda3\lib\site-packages\joblib\_parallel_backends.py", line 531, in apply_async
    """Shutdown the process or thread pool"""
  File "c:\Users\Asus\anaconda3\lib\site-packages\joblib\externals\loky\reusable_executor.py", line 177, in submit
    mp.util.debug(
  File "c:\Users\Asus\anaconda3\lib\site-packages\joblib\externals\loky\process_executor.py", line 1115, in submit
    # of the main loop of executor_manager_thread from another thread (e.g.
joblib.externals.loky.process_executor.TerminatedWorkerError: A worker process managed by the executor was unexpectedly terminated. This could be caused by a segmentation fault while calling the function or by an excessive memory usage causing the Operating System to kill the worker.

2023-11-11 15:32:29,357 - concurrent.futures - ERROR - exception calling callback for <Future at 0x18e273b63d0 state=finished raised TerminatedWorkerError>
Traceback (most recent call last):
  File "c:\Users\Asus\anaconda3\lib\site-packages\joblib\externals\loky\_base.py", line 625, in _invoke_callbacks
  File "c:\Users\Asus\anaconda3\lib\site-packages\joblib\parallel.py", line 359, in __call__
    **backend_params
  File "c:\Users\Asus\anaconda3\lib\site-packages\joblib\parallel.py", line 794, in dispatch_next
    # registers the task outcome (TASK_ERROR or TASK_DONE), and schedules
  File "c:\Users\Asus\anaconda3\lib\site-packages\joblib\parallel.py", line 861, in dispatch_one_batch
    with self.parallel._lock:
  File "c:\Users\Asus\anaconda3\lib\site-packages\joblib\parallel.py", line 779, in _dispatch
  File "c:\Users\Asus\anaconda3\lib\site-packages\joblib\_parallel_backends.py", line 531, in apply_async
    """Shutdown the process or thread pool"""
  File "c:\Users\Asus\anaconda3\lib\site-packages\joblib\externals\loky\reusable_executor.py", line 177, in submit
    mp.util.debug(
  File "c:\Users\Asus\anaconda3\lib\site-packages\joblib\externals\loky\process_executor.py", line 1115, in submit
    # of the main loop of executor_manager_thread from another thread (e.g.
joblib.externals.loky.process_executor.TerminatedWorkerError: A worker process managed by the executor was unexpectedly terminated. This could be caused by a segmentation fault while calling the function or by an excessive memory usage causing the Operating System to kill the worker.

2023-11-11 15:34:03,620 - concurrent.futures - ERROR - exception calling callback for <Future at 0x18e2a394640 state=finished raised TerminatedWorkerError>
Traceback (most recent call last):
  File "c:\Users\Asus\anaconda3\lib\site-packages\joblib\externals\loky\_base.py", line 625, in _invoke_callbacks
  File "c:\Users\Asus\anaconda3\lib\site-packages\joblib\parallel.py", line 359, in __call__
    **backend_params
  File "c:\Users\Asus\anaconda3\lib\site-packages\joblib\parallel.py", line 794, in dispatch_next
    # registers the task outcome (TASK_ERROR or TASK_DONE), and schedules
  File "c:\Users\Asus\anaconda3\lib\site-packages\joblib\parallel.py", line 861, in dispatch_one_batch
    with self.parallel._lock:
  File "c:\Users\Asus\anaconda3\lib\site-packages\joblib\parallel.py", line 779, in _dispatch
  File "c:\Users\Asus\anaconda3\lib\site-packages\joblib\_parallel_backends.py", line 531, in apply_async
    """Shutdown the process or thread pool"""
  File "c:\Users\Asus\anaconda3\lib\site-packages\joblib\externals\loky\reusable_executor.py", line 177, in submit
    mp.util.debug(
  File "c:\Users\Asus\anaconda3\lib\site-packages\joblib\externals\loky\process_executor.py", line 1115, in submit
    # of the main loop of executor_manager_thread from another thread (e.g.
joblib.externals.loky.process_executor.TerminatedWorkerError: A worker process managed by the executor was unexpectedly terminated. This could be caused by a segmentation fault while calling the function or by an excessive memory usage causing the Operating System to kill the worker.

2023-11-11 15:39:27,099 - pyswarms.single.global_best - INFO - Optimize for 10 iters with {'c1': 0.5, 'c2': 0.3, 'w': 0.9}
2023-11-11 15:40:01,804 - pyswarms.single.global_best - INFO - Optimize for 10 iters with {'c1': 0.5, 'c2': 0.3, 'w': 0.9}
2023-11-11 15:41:23,533 - pyswarms.single.global_best - INFO - Optimize for 10 iters with {'c1': 0.5, 'c2': 0.3, 'w': 0.9}
2023-11-11 15:42:22,084 - pyswarms.single.global_best - INFO - Optimize for 10 iters with {'c1': 0.5, 'c2': 0.3, 'w': 0.9}
